2024-03-27 16:40:39,331 - distributed.nanny - INFO -         Start Nanny at: 'tcp://172.16.3.171:41031'
2024-03-27 16:40:40,102 - distributed.diskutils - INFO - Found stale lock file and directory '/tmp/dask-worker-space/worker-daevgi38', purging
2024-03-27 16:40:41,823 - distributed.worker - INFO -       Start worker at:   tcp://172.16.3.171:39183
2024-03-27 16:40:41,824 - distributed.worker - INFO -          Listening to:   tcp://172.16.3.171:39183
2024-03-27 16:40:41,824 - distributed.worker - INFO -           Worker name:             SLURMCluster-0
2024-03-27 16:40:41,824 - distributed.worker - INFO -          dashboard at:         172.16.3.171:33788
2024-03-27 16:40:41,824 - distributed.worker - INFO - Waiting to connect to:    tcp://172.16.3.54:32812
2024-03-27 16:40:41,824 - distributed.worker - INFO - -------------------------------------------------
2024-03-27 16:40:41,824 - distributed.worker - INFO -               Threads:                         36
2024-03-27 16:40:41,824 - distributed.worker - INFO -                Memory:                  37.25 GiB
2024-03-27 16:40:41,824 - distributed.worker - INFO -       Local Directory: /tmp/dask-worker-space/worker-inxxd7sa
2024-03-27 16:40:41,824 - distributed.worker - INFO - -------------------------------------------------
2024-03-27 16:40:41,833 - distributed.worker - INFO -         Registered to:    tcp://172.16.3.54:32812
2024-03-27 16:40:41,833 - distributed.worker - INFO - -------------------------------------------------
2024-03-27 16:40:41,834 - distributed.core - INFO - Starting established connection to tcp://172.16.3.54:32812
2024-03-27 16:47:41,427 - distributed.worker - ERROR - Exception during execution of task ('sum-0938f01b16e648da5fcbaa17e61fb0d7', 35, 0, 0, 2).
Traceback (most recent call last):
  File "/vortexfs1/home/anthony.meza/mambaforge/envs/atm_rivers/lib/python3.10/site-packages/zict/buffer.py", line 184, in __getitem__
    return self.fast[key]
  File "/vortexfs1/home/anthony.meza/mambaforge/envs/atm_rivers/lib/python3.10/site-packages/zict/common.py", line 127, in wrapper
    return func(*args, **kwargs)
  File "/vortexfs1/home/anthony.meza/mambaforge/envs/atm_rivers/lib/python3.10/site-packages/zict/lru.py", line 117, in __getitem__
    result = self.d[key]
KeyError: "('zeros_like-9036ae164be9488350f5969335522a2f', 35, 0, 0, 2)"

During handling of the above exception, another exception occurred:

Traceback (most recent call last):
  File "/vortexfs1/home/anthony.meza/mambaforge/envs/atm_rivers/lib/python3.10/site-packages/distributed/worker.py", line 2385, in _prepare_args_for_execution
    data[k] = self.data[k]
  File "/vortexfs1/home/anthony.meza/mambaforge/envs/atm_rivers/lib/python3.10/site-packages/distributed/spill.py", line 215, in __getitem__
    return super().__getitem__(key)
  File "/vortexfs1/home/anthony.meza/mambaforge/envs/atm_rivers/lib/python3.10/site-packages/zict/common.py", line 127, in wrapper
    return func(*args, **kwargs)
  File "/vortexfs1/home/anthony.meza/mambaforge/envs/atm_rivers/lib/python3.10/site-packages/zict/buffer.py", line 186, in __getitem__
    return self.slow_to_fast(key)
  File "/vortexfs1/home/anthony.meza/mambaforge/envs/atm_rivers/lib/python3.10/site-packages/zict/buffer.py", line 153, in slow_to_fast
    value = self.slow[key]
  File "/vortexfs1/home/anthony.meza/mambaforge/envs/atm_rivers/lib/python3.10/site-packages/zict/common.py", line 127, in wrapper
    return func(*args, **kwargs)
  File "/vortexfs1/home/anthony.meza/mambaforge/envs/atm_rivers/lib/python3.10/site-packages/zict/cache.py", line 67, in __getitem__
    gen = self._last_updated[key]
KeyError: "('zeros_like-9036ae164be9488350f5969335522a2f', 35, 0, 0, 2)"

During handling of the above exception, another exception occurred:

Traceback (most recent call last):
  File "/vortexfs1/home/anthony.meza/mambaforge/envs/atm_rivers/lib/python3.10/site-packages/distributed/worker.py", line 2253, in execute
    args2, kwargs2 = self._prepare_args_for_execution(ts, args, kwargs)
  File "/vortexfs1/home/anthony.meza/mambaforge/envs/atm_rivers/lib/python3.10/site-packages/distributed/worker.py", line 2389, in _prepare_args_for_execution
    data[k] = Actor(type(self.state.actors[k]), self.address, k, self)
KeyError: "('zeros_like-9036ae164be9488350f5969335522a2f', 35, 0, 0, 2)"
2024-03-27 16:47:41,459 - distributed.worker - ERROR - Exception during execution of task ('sum-0938f01b16e648da5fcbaa17e61fb0d7', 35, 0, 1, 2).
Traceback (most recent call last):
  File "/vortexfs1/home/anthony.meza/mambaforge/envs/atm_rivers/lib/python3.10/site-packages/zict/buffer.py", line 184, in __getitem__
    return self.fast[key]
  File "/vortexfs1/home/anthony.meza/mambaforge/envs/atm_rivers/lib/python3.10/site-packages/zict/common.py", line 127, in wrapper
    return func(*args, **kwargs)
  File "/vortexfs1/home/anthony.meza/mambaforge/envs/atm_rivers/lib/python3.10/site-packages/zict/lru.py", line 117, in __getitem__
    result = self.d[key]
KeyError: "('zeros_like-9036ae164be9488350f5969335522a2f', 35, 0, 1, 2)"

During handling of the above exception, another exception occurred:

Traceback (most recent call last):
  File "/vortexfs1/home/anthony.meza/mambaforge/envs/atm_rivers/lib/python3.10/site-packages/distributed/worker.py", line 2385, in _prepare_args_for_execution
    data[k] = self.data[k]
  File "/vortexfs1/home/anthony.meza/mambaforge/envs/atm_rivers/lib/python3.10/site-packages/distributed/spill.py", line 215, in __getitem__
    return super().__getitem__(key)
  File "/vortexfs1/home/anthony.meza/mambaforge/envs/atm_rivers/lib/python3.10/site-packages/zict/common.py", line 127, in wrapper
    return func(*args, **kwargs)
  File "/vortexfs1/home/anthony.meza/mambaforge/envs/atm_rivers/lib/python3.10/site-packages/zict/buffer.py", line 186, in __getitem__
    return self.slow_to_fast(key)
  File "/vortexfs1/home/anthony.meza/mambaforge/envs/atm_rivers/lib/python3.10/site-packages/zict/buffer.py", line 153, in slow_to_fast
    value = self.slow[key]
  File "/vortexfs1/home/anthony.meza/mambaforge/envs/atm_rivers/lib/python3.10/site-packages/zict/common.py", line 127, in wrapper
    return func(*args, **kwargs)
  File "/vortexfs1/home/anthony.meza/mambaforge/envs/atm_rivers/lib/python3.10/site-packages/zict/cache.py", line 67, in __getitem__
    gen = self._last_updated[key]
KeyError: "('zeros_like-9036ae164be9488350f5969335522a2f', 35, 0, 1, 2)"

During handling of the above exception, another exception occurred:

Traceback (most recent call last):
  File "/vortexfs1/home/anthony.meza/mambaforge/envs/atm_rivers/lib/python3.10/site-packages/distributed/worker.py", line 2253, in execute
    args2, kwargs2 = self._prepare_args_for_execution(ts, args, kwargs)
  File "/vortexfs1/home/anthony.meza/mambaforge/envs/atm_rivers/lib/python3.10/site-packages/distributed/worker.py", line 2389, in _prepare_args_for_execution
    data[k] = Actor(type(self.state.actors[k]), self.address, k, self)
KeyError: "('zeros_like-9036ae164be9488350f5969335522a2f', 35, 0, 1, 2)"
2024-03-27 16:47:41,460 - distributed.worker - ERROR - Exception during execution of task ('sum-e9429b7246a1038dc5e7b24ce618dd7c', 35, 0, 0, 2).
Traceback (most recent call last):
  File "/vortexfs1/home/anthony.meza/mambaforge/envs/atm_rivers/lib/python3.10/site-packages/zict/buffer.py", line 184, in __getitem__
    return self.fast[key]
  File "/vortexfs1/home/anthony.meza/mambaforge/envs/atm_rivers/lib/python3.10/site-packages/zict/common.py", line 127, in wrapper
    return func(*args, **kwargs)
  File "/vortexfs1/home/anthony.meza/mambaforge/envs/atm_rivers/lib/python3.10/site-packages/zict/lru.py", line 117, in __getitem__
    result = self.d[key]
KeyError: "('zeros_like-9036ae164be9488350f5969335522a2f', 35, 0, 0, 2)"

During handling of the above exception, another exception occurred:

Traceback (most recent call last):
  File "/vortexfs1/home/anthony.meza/mambaforge/envs/atm_rivers/lib/python3.10/site-packages/distributed/worker.py", line 2385, in _prepare_args_for_execution
    data[k] = self.data[k]
  File "/vortexfs1/home/anthony.meza/mambaforge/envs/atm_rivers/lib/python3.10/site-packages/distributed/spill.py", line 215, in __getitem__
    return super().__getitem__(key)
  File "/vortexfs1/home/anthony.meza/mambaforge/envs/atm_rivers/lib/python3.10/site-packages/zict/common.py", line 127, in wrapper
    return func(*args, **kwargs)
  File "/vortexfs1/home/anthony.meza/mambaforge/envs/atm_rivers/lib/python3.10/site-packages/zict/buffer.py", line 186, in __getitem__
    return self.slow_to_fast(key)
  File "/vortexfs1/home/anthony.meza/mambaforge/envs/atm_rivers/lib/python3.10/site-packages/zict/buffer.py", line 153, in slow_to_fast
    value = self.slow[key]
  File "/vortexfs1/home/anthony.meza/mambaforge/envs/atm_rivers/lib/python3.10/site-packages/zict/common.py", line 127, in wrapper
    return func(*args, **kwargs)
  File "/vortexfs1/home/anthony.meza/mambaforge/envs/atm_rivers/lib/python3.10/site-packages/zict/cache.py", line 67, in __getitem__
    gen = self._last_updated[key]
KeyError: "('zeros_like-9036ae164be9488350f5969335522a2f', 35, 0, 0, 2)"

During handling of the above exception, another exception occurred:

Traceback (most recent call last):
  File "/vortexfs1/home/anthony.meza/mambaforge/envs/atm_rivers/lib/python3.10/site-packages/distributed/worker.py", line 2253, in execute
    args2, kwargs2 = self._prepare_args_for_execution(ts, args, kwargs)
  File "/vortexfs1/home/anthony.meza/mambaforge/envs/atm_rivers/lib/python3.10/site-packages/distributed/worker.py", line 2389, in _prepare_args_for_execution
    data[k] = Actor(type(self.state.actors[k]), self.address, k, self)
KeyError: "('zeros_like-9036ae164be9488350f5969335522a2f', 35, 0, 0, 2)"
2024-03-27 18:25:52,714 - distributed.core - INFO - Connection to tcp://172.16.3.54:32812 has been closed.
2024-03-27 18:25:52,715 - distributed.worker - INFO - Stopping worker at tcp://172.16.3.171:39183. Reason: worker-handle-scheduler-connection-broken
2024-03-27 18:25:52,717 - distributed.nanny - INFO - Closing Nanny gracefully at 'tcp://172.16.3.171:41031'. Reason: worker-handle-scheduler-connection-broken
2024-03-27 18:25:52,727 - distributed.nanny - INFO - Worker closed
2024-03-27 18:25:54,731 - distributed.nanny - ERROR - Worker process died unexpectedly
2024-03-27 18:25:55,018 - distributed.nanny - INFO - Closing Nanny at 'tcp://172.16.3.171:41031'. Reason: nanny-close-gracefully
2024-03-27 18:25:55,018 - distributed.dask_worker - INFO - End worker
