2024-03-27 16:40:45,180 - distributed.nanny - INFO -         Start Nanny at: 'tcp://172.16.3.184:32919'
2024-03-27 16:40:53,585 - distributed.worker - INFO -       Start worker at:   tcp://172.16.3.184:35945
2024-03-27 16:40:53,587 - distributed.worker - INFO -          Listening to:   tcp://172.16.3.184:35945
2024-03-27 16:40:53,587 - distributed.worker - INFO -           Worker name:             SLURMCluster-9
2024-03-27 16:40:53,587 - distributed.worker - INFO -          dashboard at:         172.16.3.184:46595
2024-03-27 16:40:53,587 - distributed.worker - INFO - Waiting to connect to:    tcp://172.16.3.54:32812
2024-03-27 16:40:53,587 - distributed.worker - INFO - -------------------------------------------------
2024-03-27 16:40:53,587 - distributed.worker - INFO -               Threads:                         36
2024-03-27 16:40:53,587 - distributed.worker - INFO -                Memory:                  37.25 GiB
2024-03-27 16:40:53,587 - distributed.worker - INFO -       Local Directory: /tmp/dask-worker-space/worker-dntx9jxl
2024-03-27 16:40:53,587 - distributed.worker - INFO - -------------------------------------------------
2024-03-27 16:40:53,621 - distributed.worker - INFO -         Registered to:    tcp://172.16.3.54:32812
2024-03-27 16:40:53,621 - distributed.worker - INFO - -------------------------------------------------
2024-03-27 16:40:53,622 - distributed.core - INFO - Starting established connection to tcp://172.16.3.54:32812
2024-03-27 16:47:41,569 - distributed.worker - ERROR - Exception during execution of task ('sum-e9429b7246a1038dc5e7b24ce618dd7c', 144, 0, 0, 2).
Traceback (most recent call last):
  File "/vortexfs1/home/anthony.meza/mambaforge/envs/atm_rivers/lib/python3.10/site-packages/zict/buffer.py", line 184, in __getitem__
    return self.fast[key]
  File "/vortexfs1/home/anthony.meza/mambaforge/envs/atm_rivers/lib/python3.10/site-packages/zict/common.py", line 127, in wrapper
    return func(*args, **kwargs)
  File "/vortexfs1/home/anthony.meza/mambaforge/envs/atm_rivers/lib/python3.10/site-packages/zict/lru.py", line 117, in __getitem__
    result = self.d[key]
KeyError: "('zeros_like-9036ae164be9488350f5969335522a2f', 144, 0, 0, 2)"

During handling of the above exception, another exception occurred:

Traceback (most recent call last):
  File "/vortexfs1/home/anthony.meza/mambaforge/envs/atm_rivers/lib/python3.10/site-packages/distributed/worker.py", line 2385, in _prepare_args_for_execution
    data[k] = self.data[k]
  File "/vortexfs1/home/anthony.meza/mambaforge/envs/atm_rivers/lib/python3.10/site-packages/distributed/spill.py", line 215, in __getitem__
    return super().__getitem__(key)
  File "/vortexfs1/home/anthony.meza/mambaforge/envs/atm_rivers/lib/python3.10/site-packages/zict/common.py", line 127, in wrapper
    return func(*args, **kwargs)
  File "/vortexfs1/home/anthony.meza/mambaforge/envs/atm_rivers/lib/python3.10/site-packages/zict/buffer.py", line 186, in __getitem__
    return self.slow_to_fast(key)
  File "/vortexfs1/home/anthony.meza/mambaforge/envs/atm_rivers/lib/python3.10/site-packages/zict/buffer.py", line 153, in slow_to_fast
    value = self.slow[key]
  File "/vortexfs1/home/anthony.meza/mambaforge/envs/atm_rivers/lib/python3.10/site-packages/zict/common.py", line 127, in wrapper
    return func(*args, **kwargs)
  File "/vortexfs1/home/anthony.meza/mambaforge/envs/atm_rivers/lib/python3.10/site-packages/zict/cache.py", line 67, in __getitem__
    gen = self._last_updated[key]
KeyError: "('zeros_like-9036ae164be9488350f5969335522a2f', 144, 0, 0, 2)"

During handling of the above exception, another exception occurred:

Traceback (most recent call last):
  File "/vortexfs1/home/anthony.meza/mambaforge/envs/atm_rivers/lib/python3.10/site-packages/distributed/worker.py", line 2253, in execute
    args2, kwargs2 = self._prepare_args_for_execution(ts, args, kwargs)
  File "/vortexfs1/home/anthony.meza/mambaforge/envs/atm_rivers/lib/python3.10/site-packages/distributed/worker.py", line 2389, in _prepare_args_for_execution
    data[k] = Actor(type(self.state.actors[k]), self.address, k, self)
KeyError: "('zeros_like-9036ae164be9488350f5969335522a2f', 144, 0, 0, 2)"
2024-03-27 16:47:41,587 - distributed.worker - ERROR - Exception during execution of task ('sum-897174aa0132ee17c46799d5a1639bff', 144, 0, 0, 2).
Traceback (most recent call last):
  File "/vortexfs1/home/anthony.meza/mambaforge/envs/atm_rivers/lib/python3.10/site-packages/zict/buffer.py", line 184, in __getitem__
    return self.fast[key]
  File "/vortexfs1/home/anthony.meza/mambaforge/envs/atm_rivers/lib/python3.10/site-packages/zict/common.py", line 127, in wrapper
    return func(*args, **kwargs)
  File "/vortexfs1/home/anthony.meza/mambaforge/envs/atm_rivers/lib/python3.10/site-packages/zict/lru.py", line 117, in __getitem__
    result = self.d[key]
KeyError: "('zeros_like-9036ae164be9488350f5969335522a2f', 144, 0, 0, 2)"

During handling of the above exception, another exception occurred:

Traceback (most recent call last):
  File "/vortexfs1/home/anthony.meza/mambaforge/envs/atm_rivers/lib/python3.10/site-packages/distributed/worker.py", line 2385, in _prepare_args_for_execution
    data[k] = self.data[k]
  File "/vortexfs1/home/anthony.meza/mambaforge/envs/atm_rivers/lib/python3.10/site-packages/distributed/spill.py", line 215, in __getitem__
    return super().__getitem__(key)
  File "/vortexfs1/home/anthony.meza/mambaforge/envs/atm_rivers/lib/python3.10/site-packages/zict/common.py", line 127, in wrapper
    return func(*args, **kwargs)
  File "/vortexfs1/home/anthony.meza/mambaforge/envs/atm_rivers/lib/python3.10/site-packages/zict/buffer.py", line 186, in __getitem__
    return self.slow_to_fast(key)
  File "/vortexfs1/home/anthony.meza/mambaforge/envs/atm_rivers/lib/python3.10/site-packages/zict/buffer.py", line 153, in slow_to_fast
    value = self.slow[key]
  File "/vortexfs1/home/anthony.meza/mambaforge/envs/atm_rivers/lib/python3.10/site-packages/zict/common.py", line 127, in wrapper
    return func(*args, **kwargs)
  File "/vortexfs1/home/anthony.meza/mambaforge/envs/atm_rivers/lib/python3.10/site-packages/zict/cache.py", line 67, in __getitem__
    gen = self._last_updated[key]
KeyError: "('zeros_like-9036ae164be9488350f5969335522a2f', 144, 0, 0, 2)"

During handling of the above exception, another exception occurred:

Traceback (most recent call last):
  File "/vortexfs1/home/anthony.meza/mambaforge/envs/atm_rivers/lib/python3.10/site-packages/distributed/worker.py", line 2253, in execute
    args2, kwargs2 = self._prepare_args_for_execution(ts, args, kwargs)
  File "/vortexfs1/home/anthony.meza/mambaforge/envs/atm_rivers/lib/python3.10/site-packages/distributed/worker.py", line 2389, in _prepare_args_for_execution
    data[k] = Actor(type(self.state.actors[k]), self.address, k, self)
KeyError: "('zeros_like-9036ae164be9488350f5969335522a2f', 144, 0, 0, 2)"
2024-03-27 16:47:41,588 - distributed.worker - ERROR - Exception during execution of task ('sum-366e116973b46f2520dc65a00b7e1f3d', 144, 0, 0, 2).
Traceback (most recent call last):
  File "/vortexfs1/home/anthony.meza/mambaforge/envs/atm_rivers/lib/python3.10/site-packages/zict/buffer.py", line 184, in __getitem__
    return self.fast[key]
  File "/vortexfs1/home/anthony.meza/mambaforge/envs/atm_rivers/lib/python3.10/site-packages/zict/common.py", line 127, in wrapper
    return func(*args, **kwargs)
  File "/vortexfs1/home/anthony.meza/mambaforge/envs/atm_rivers/lib/python3.10/site-packages/zict/lru.py", line 117, in __getitem__
    result = self.d[key]
KeyError: 'original-open_dataset-bd8eb8ef8c10c383a9d8509575be050acfc12-c0a98faa329185ee79cb2bbc17c16b3e'

During handling of the above exception, another exception occurred:

Traceback (most recent call last):
  File "/vortexfs1/home/anthony.meza/mambaforge/envs/atm_rivers/lib/python3.10/site-packages/distributed/worker.py", line 2385, in _prepare_args_for_execution
    data[k] = self.data[k]
  File "/vortexfs1/home/anthony.meza/mambaforge/envs/atm_rivers/lib/python3.10/site-packages/distributed/spill.py", line 215, in __getitem__
    return super().__getitem__(key)
  File "/vortexfs1/home/anthony.meza/mambaforge/envs/atm_rivers/lib/python3.10/site-packages/zict/common.py", line 127, in wrapper
    return func(*args, **kwargs)
  File "/vortexfs1/home/anthony.meza/mambaforge/envs/atm_rivers/lib/python3.10/site-packages/zict/buffer.py", line 186, in __getitem__
    return self.slow_to_fast(key)
  File "/vortexfs1/home/anthony.meza/mambaforge/envs/atm_rivers/lib/python3.10/site-packages/zict/buffer.py", line 153, in slow_to_fast
    value = self.slow[key]
  File "/vortexfs1/home/anthony.meza/mambaforge/envs/atm_rivers/lib/python3.10/site-packages/zict/common.py", line 127, in wrapper
    return func(*args, **kwargs)
  File "/vortexfs1/home/anthony.meza/mambaforge/envs/atm_rivers/lib/python3.10/site-packages/zict/cache.py", line 67, in __getitem__
    gen = self._last_updated[key]
KeyError: 'original-open_dataset-bd8eb8ef8c10c383a9d8509575be050acfc12-c0a98faa329185ee79cb2bbc17c16b3e'

During handling of the above exception, another exception occurred:

Traceback (most recent call last):
  File "/vortexfs1/home/anthony.meza/mambaforge/envs/atm_rivers/lib/python3.10/site-packages/distributed/worker.py", line 2253, in execute
    args2, kwargs2 = self._prepare_args_for_execution(ts, args, kwargs)
  File "/vortexfs1/home/anthony.meza/mambaforge/envs/atm_rivers/lib/python3.10/site-packages/distributed/worker.py", line 2389, in _prepare_args_for_execution
    data[k] = Actor(type(self.state.actors[k]), self.address, k, self)
KeyError: 'original-open_dataset-bd8eb8ef8c10c383a9d8509575be050acfc12-c0a98faa329185ee79cb2bbc17c16b3e'
2024-03-27 18:25:52,713 - distributed.core - INFO - Connection to tcp://172.16.3.54:32812 has been closed.
2024-03-27 18:25:52,714 - distributed.worker - INFO - Stopping worker at tcp://172.16.3.184:35945. Reason: worker-handle-scheduler-connection-broken
2024-03-27 18:25:52,714 - distributed.worker - ERROR - Failed to communicate with scheduler during heartbeat.
Traceback (most recent call last):
  File "/vortexfs1/home/anthony.meza/mambaforge/envs/atm_rivers/lib/python3.10/site-packages/tornado/iostream.py", line 861, in _read_to_buffer
    bytes_read = self.read_from_fd(buf)
  File "/vortexfs1/home/anthony.meza/mambaforge/envs/atm_rivers/lib/python3.10/site-packages/tornado/iostream.py", line 1116, in read_from_fd
    return self.socket.recv_into(buf, len(buf))
ConnectionResetError: [Errno 104] Connection reset by peer

The above exception was the direct cause of the following exception:

Traceback (most recent call last):
  File "/vortexfs1/home/anthony.meza/mambaforge/envs/atm_rivers/lib/python3.10/site-packages/distributed/worker.py", line 1237, in heartbeat
    response = await retry_operation(
  File "/vortexfs1/home/anthony.meza/mambaforge/envs/atm_rivers/lib/python3.10/site-packages/distributed/utils_comm.py", line 434, in retry_operation
    return await retry(
  File "/vortexfs1/home/anthony.meza/mambaforge/envs/atm_rivers/lib/python3.10/site-packages/distributed/utils_comm.py", line 413, in retry
    return await coro()
  File "/vortexfs1/home/anthony.meza/mambaforge/envs/atm_rivers/lib/python3.10/site-packages/distributed/core.py", line 1269, in send_recv_from_rpc
    return await send_recv(comm=comm, op=key, **kwargs)
  File "/vortexfs1/home/anthony.meza/mambaforge/envs/atm_rivers/lib/python3.10/site-packages/distributed/core.py", line 1028, in send_recv
    response = await comm.read(deserializers=deserializers)
  File "/vortexfs1/home/anthony.meza/mambaforge/envs/atm_rivers/lib/python3.10/site-packages/distributed/comm/tcp.py", line 241, in read
    convert_stream_closed_error(self, e)
  File "/vortexfs1/home/anthony.meza/mambaforge/envs/atm_rivers/lib/python3.10/site-packages/distributed/comm/tcp.py", line 142, in convert_stream_closed_error
    raise CommClosedError(f"in {obj}: {exc.__class__.__name__}: {exc}") from exc
distributed.comm.core.CommClosedError: in <TCP (closed) ConnectionPool.heartbeat_worker local=tcp://172.16.3.184:51071 remote=tcp://172.16.3.54:32812>: ConnectionResetError: [Errno 104] Connection reset by peer
2024-03-27 18:25:52,725 - distributed.nanny - INFO - Closing Nanny gracefully at 'tcp://172.16.3.184:32919'. Reason: worker-handle-scheduler-connection-broken
2024-03-27 18:25:52,732 - distributed.nanny - INFO - Worker closed
2024-03-27 18:25:54,734 - distributed.nanny - ERROR - Worker process died unexpectedly
2024-03-27 18:25:55,034 - distributed.nanny - INFO - Closing Nanny at 'tcp://172.16.3.184:32919'. Reason: nanny-close-gracefully
2024-03-27 18:25:55,035 - distributed.dask_worker - INFO - End worker
