2024-03-27 16:40:41,862 - distributed.nanny - INFO -         Start Nanny at: 'tcp://172.16.3.120:33665'
2024-03-27 16:40:47,839 - distributed.worker - INFO -       Start worker at:   tcp://172.16.3.120:35068
2024-03-27 16:40:47,841 - distributed.worker - INFO -          Listening to:   tcp://172.16.3.120:35068
2024-03-27 16:40:47,841 - distributed.worker - INFO -           Worker name:             SLURMCluster-1
2024-03-27 16:40:47,841 - distributed.worker - INFO -          dashboard at:         172.16.3.120:33108
2024-03-27 16:40:47,841 - distributed.worker - INFO - Waiting to connect to:    tcp://172.16.3.54:32812
2024-03-27 16:40:47,841 - distributed.worker - INFO - -------------------------------------------------
2024-03-27 16:40:47,841 - distributed.worker - INFO -               Threads:                         36
2024-03-27 16:40:47,841 - distributed.worker - INFO -                Memory:                  37.25 GiB
2024-03-27 16:40:47,841 - distributed.worker - INFO -       Local Directory: /tmp/dask-worker-space/worker-8epyzx0y
2024-03-27 16:40:47,841 - distributed.worker - INFO - -------------------------------------------------
2024-03-27 16:40:47,858 - distributed.worker - INFO -         Registered to:    tcp://172.16.3.54:32812
2024-03-27 16:40:47,858 - distributed.worker - INFO - -------------------------------------------------
2024-03-27 16:40:47,858 - distributed.core - INFO - Starting established connection to tcp://172.16.3.54:32812
2024-03-27 16:47:41,385 - distributed.worker - ERROR - Exception during execution of task ('sum-e9429b7246a1038dc5e7b24ce618dd7c', 160, 0, 1, 0).
Traceback (most recent call last):
  File "/vortexfs1/home/anthony.meza/mambaforge/envs/atm_rivers/lib/python3.10/site-packages/zict/buffer.py", line 184, in __getitem__
    return self.fast[key]
  File "/vortexfs1/home/anthony.meza/mambaforge/envs/atm_rivers/lib/python3.10/site-packages/zict/common.py", line 127, in wrapper
    return func(*args, **kwargs)
  File "/vortexfs1/home/anthony.meza/mambaforge/envs/atm_rivers/lib/python3.10/site-packages/zict/lru.py", line 117, in __getitem__
    result = self.d[key]
KeyError: "('open_dataset-bd8eb8ef8c10c383a9d8509575be050athkcello-2b1dc39d0a6b4bcd1625116a411686bc', 160, 0, 1, 0)"

During handling of the above exception, another exception occurred:

Traceback (most recent call last):
  File "/vortexfs1/home/anthony.meza/mambaforge/envs/atm_rivers/lib/python3.10/site-packages/distributed/worker.py", line 2385, in _prepare_args_for_execution
    data[k] = self.data[k]
  File "/vortexfs1/home/anthony.meza/mambaforge/envs/atm_rivers/lib/python3.10/site-packages/distributed/spill.py", line 215, in __getitem__
    return super().__getitem__(key)
  File "/vortexfs1/home/anthony.meza/mambaforge/envs/atm_rivers/lib/python3.10/site-packages/zict/common.py", line 127, in wrapper
    return func(*args, **kwargs)
  File "/vortexfs1/home/anthony.meza/mambaforge/envs/atm_rivers/lib/python3.10/site-packages/zict/buffer.py", line 186, in __getitem__
    return self.slow_to_fast(key)
  File "/vortexfs1/home/anthony.meza/mambaforge/envs/atm_rivers/lib/python3.10/site-packages/zict/buffer.py", line 153, in slow_to_fast
    value = self.slow[key]
  File "/vortexfs1/home/anthony.meza/mambaforge/envs/atm_rivers/lib/python3.10/site-packages/zict/common.py", line 127, in wrapper
    return func(*args, **kwargs)
  File "/vortexfs1/home/anthony.meza/mambaforge/envs/atm_rivers/lib/python3.10/site-packages/zict/cache.py", line 67, in __getitem__
    gen = self._last_updated[key]
KeyError: "('open_dataset-bd8eb8ef8c10c383a9d8509575be050athkcello-2b1dc39d0a6b4bcd1625116a411686bc', 160, 0, 1, 0)"

During handling of the above exception, another exception occurred:

Traceback (most recent call last):
  File "/vortexfs1/home/anthony.meza/mambaforge/envs/atm_rivers/lib/python3.10/site-packages/distributed/worker.py", line 2253, in execute
    args2, kwargs2 = self._prepare_args_for_execution(ts, args, kwargs)
  File "/vortexfs1/home/anthony.meza/mambaforge/envs/atm_rivers/lib/python3.10/site-packages/distributed/worker.py", line 2389, in _prepare_args_for_execution
    data[k] = Actor(type(self.state.actors[k]), self.address, k, self)
KeyError: "('open_dataset-bd8eb8ef8c10c383a9d8509575be050athkcello-2b1dc39d0a6b4bcd1625116a411686bc', 160, 0, 1, 0)"
2024-03-27 16:47:41,402 - distributed.worker - ERROR - Exception during execution of task ('sum-897174aa0132ee17c46799d5a1639bff', 160, 0, 1, 0).
Traceback (most recent call last):
  File "/vortexfs1/home/anthony.meza/mambaforge/envs/atm_rivers/lib/python3.10/site-packages/zict/buffer.py", line 184, in __getitem__
    return self.fast[key]
  File "/vortexfs1/home/anthony.meza/mambaforge/envs/atm_rivers/lib/python3.10/site-packages/zict/common.py", line 127, in wrapper
    return func(*args, **kwargs)
  File "/vortexfs1/home/anthony.meza/mambaforge/envs/atm_rivers/lib/python3.10/site-packages/zict/lru.py", line 117, in __getitem__
    result = self.d[key]
KeyError: "('open_dataset-bd8eb8ef8c10c383a9d8509575be050athkcello-2b1dc39d0a6b4bcd1625116a411686bc', 160, 0, 1, 0)"

During handling of the above exception, another exception occurred:

Traceback (most recent call last):
  File "/vortexfs1/home/anthony.meza/mambaforge/envs/atm_rivers/lib/python3.10/site-packages/distributed/worker.py", line 2385, in _prepare_args_for_execution
    data[k] = self.data[k]
  File "/vortexfs1/home/anthony.meza/mambaforge/envs/atm_rivers/lib/python3.10/site-packages/distributed/spill.py", line 215, in __getitem__
    return super().__getitem__(key)
  File "/vortexfs1/home/anthony.meza/mambaforge/envs/atm_rivers/lib/python3.10/site-packages/zict/common.py", line 127, in wrapper
    return func(*args, **kwargs)
  File "/vortexfs1/home/anthony.meza/mambaforge/envs/atm_rivers/lib/python3.10/site-packages/zict/buffer.py", line 186, in __getitem__
    return self.slow_to_fast(key)
  File "/vortexfs1/home/anthony.meza/mambaforge/envs/atm_rivers/lib/python3.10/site-packages/zict/buffer.py", line 153, in slow_to_fast
    value = self.slow[key]
  File "/vortexfs1/home/anthony.meza/mambaforge/envs/atm_rivers/lib/python3.10/site-packages/zict/common.py", line 127, in wrapper
    return func(*args, **kwargs)
  File "/vortexfs1/home/anthony.meza/mambaforge/envs/atm_rivers/lib/python3.10/site-packages/zict/cache.py", line 67, in __getitem__
    gen = self._last_updated[key]
KeyError: "('open_dataset-bd8eb8ef8c10c383a9d8509575be050athkcello-2b1dc39d0a6b4bcd1625116a411686bc', 160, 0, 1, 0)"

During handling of the above exception, another exception occurred:

Traceback (most recent call last):
  File "/vortexfs1/home/anthony.meza/mambaforge/envs/atm_rivers/lib/python3.10/site-packages/distributed/worker.py", line 2253, in execute
    args2, kwargs2 = self._prepare_args_for_execution(ts, args, kwargs)
  File "/vortexfs1/home/anthony.meza/mambaforge/envs/atm_rivers/lib/python3.10/site-packages/distributed/worker.py", line 2389, in _prepare_args_for_execution
    data[k] = Actor(type(self.state.actors[k]), self.address, k, self)
KeyError: "('open_dataset-bd8eb8ef8c10c383a9d8509575be050athkcello-2b1dc39d0a6b4bcd1625116a411686bc', 160, 0, 1, 0)"
2024-03-27 16:47:47,659 - distributed.utils_perf - INFO - full garbage collection released 38.32 MiB from 2374 reference cycles (threshold: 9.54 MiB)
2024-03-27 18:25:52,712 - distributed.core - INFO - Connection to tcp://172.16.3.54:32812 has been closed.
2024-03-27 18:25:52,714 - distributed.worker - INFO - Stopping worker at tcp://172.16.3.120:35068. Reason: worker-handle-scheduler-connection-broken
2024-03-27 18:25:52,716 - distributed.nanny - INFO - Closing Nanny gracefully at 'tcp://172.16.3.120:33665'. Reason: worker-handle-scheduler-connection-broken
2024-03-27 18:25:52,765 - distributed.nanny - INFO - Worker closed
2024-03-27 18:25:54,769 - distributed.nanny - ERROR - Worker process died unexpectedly
2024-03-27 18:25:55,991 - distributed.nanny - INFO - Closing Nanny at 'tcp://172.16.3.120:33665'. Reason: nanny-close-gracefully
2024-03-27 18:25:55,992 - distributed.dask_worker - INFO - End worker
