2024-03-27 16:40:59,886 - distributed.nanny - INFO -         Start Nanny at: 'tcp://172.16.3.221:36025'
2024-03-27 16:41:14,335 - distributed.worker - INFO -       Start worker at:   tcp://172.16.3.221:41996
2024-03-27 16:41:14,338 - distributed.worker - INFO -          Listening to:   tcp://172.16.3.221:41996
2024-03-27 16:41:14,338 - distributed.worker - INFO -           Worker name:            SLURMCluster-11
2024-03-27 16:41:14,338 - distributed.worker - INFO -          dashboard at:         172.16.3.221:34084
2024-03-27 16:41:14,338 - distributed.worker - INFO - Waiting to connect to:    tcp://172.16.3.54:32812
2024-03-27 16:41:14,338 - distributed.worker - INFO - -------------------------------------------------
2024-03-27 16:41:14,338 - distributed.worker - INFO -               Threads:                         36
2024-03-27 16:41:14,338 - distributed.worker - INFO -                Memory:                  37.25 GiB
2024-03-27 16:41:14,338 - distributed.worker - INFO -       Local Directory: /tmp/dask-worker-space/worker-e2t073ol
2024-03-27 16:41:14,338 - distributed.worker - INFO - -------------------------------------------------
2024-03-27 16:41:14,375 - distributed.worker - INFO -         Registered to:    tcp://172.16.3.54:32812
2024-03-27 16:41:14,375 - distributed.worker - INFO - -------------------------------------------------
2024-03-27 16:41:14,375 - distributed.core - INFO - Starting established connection to tcp://172.16.3.54:32812
2024-03-27 16:41:33,815 - distributed.core - INFO - Event loop was unresponsive in Worker for 3.16s.  This is often caused by long-running GIL-holding functions or moving large chunks of data. This can cause timeouts and instability.
2024-03-27 16:47:41,772 - distributed.worker - ERROR - Exception during execution of task ('open_dataset-bd8eb8ef8c10c383a9d8509575be050athkcello-2b1dc39d0a6b4bcd1625116a411686bc', 158, 0, 2, 1).
Traceback (most recent call last):
  File "/vortexfs1/home/anthony.meza/mambaforge/envs/atm_rivers/lib/python3.10/site-packages/zict/buffer.py", line 184, in __getitem__
    return self.fast[key]
  File "/vortexfs1/home/anthony.meza/mambaforge/envs/atm_rivers/lib/python3.10/site-packages/zict/common.py", line 127, in wrapper
    return func(*args, **kwargs)
  File "/vortexfs1/home/anthony.meza/mambaforge/envs/atm_rivers/lib/python3.10/site-packages/zict/lru.py", line 117, in __getitem__
    result = self.d[key]
KeyError: 'original-open_dataset-bd8eb8ef8c10c383a9d8509575be050athkcello-2b1dc39d0a6b4bcd1625116a411686bc'

During handling of the above exception, another exception occurred:

Traceback (most recent call last):
  File "/vortexfs1/home/anthony.meza/mambaforge/envs/atm_rivers/lib/python3.10/site-packages/distributed/worker.py", line 2385, in _prepare_args_for_execution
    data[k] = self.data[k]
  File "/vortexfs1/home/anthony.meza/mambaforge/envs/atm_rivers/lib/python3.10/site-packages/distributed/spill.py", line 215, in __getitem__
    return super().__getitem__(key)
  File "/vortexfs1/home/anthony.meza/mambaforge/envs/atm_rivers/lib/python3.10/site-packages/zict/common.py", line 127, in wrapper
    return func(*args, **kwargs)
  File "/vortexfs1/home/anthony.meza/mambaforge/envs/atm_rivers/lib/python3.10/site-packages/zict/buffer.py", line 186, in __getitem__
    return self.slow_to_fast(key)
  File "/vortexfs1/home/anthony.meza/mambaforge/envs/atm_rivers/lib/python3.10/site-packages/zict/buffer.py", line 153, in slow_to_fast
    value = self.slow[key]
  File "/vortexfs1/home/anthony.meza/mambaforge/envs/atm_rivers/lib/python3.10/site-packages/zict/common.py", line 127, in wrapper
    return func(*args, **kwargs)
  File "/vortexfs1/home/anthony.meza/mambaforge/envs/atm_rivers/lib/python3.10/site-packages/zict/cache.py", line 67, in __getitem__
    gen = self._last_updated[key]
KeyError: 'original-open_dataset-bd8eb8ef8c10c383a9d8509575be050athkcello-2b1dc39d0a6b4bcd1625116a411686bc'

During handling of the above exception, another exception occurred:

Traceback (most recent call last):
  File "/vortexfs1/home/anthony.meza/mambaforge/envs/atm_rivers/lib/python3.10/site-packages/distributed/worker.py", line 2253, in execute
    args2, kwargs2 = self._prepare_args_for_execution(ts, args, kwargs)
  File "/vortexfs1/home/anthony.meza/mambaforge/envs/atm_rivers/lib/python3.10/site-packages/distributed/worker.py", line 2389, in _prepare_args_for_execution
    data[k] = Actor(type(self.state.actors[k]), self.address, k, self)
KeyError: 'original-open_dataset-bd8eb8ef8c10c383a9d8509575be050athkcello-2b1dc39d0a6b4bcd1625116a411686bc'
2024-03-27 18:25:52,713 - distributed.core - INFO - Connection to tcp://172.16.3.54:32812 has been closed.
2024-03-27 18:25:52,714 - distributed.worker - INFO - Stopping worker at tcp://172.16.3.221:41996. Reason: worker-handle-scheduler-connection-broken
2024-03-27 18:25:52,717 - distributed.nanny - INFO - Closing Nanny gracefully at 'tcp://172.16.3.221:36025'. Reason: worker-handle-scheduler-connection-broken
2024-03-27 18:25:52,726 - distributed.nanny - INFO - Worker closed
2024-03-27 18:25:55,083 - distributed.nanny - INFO - Closing Nanny at 'tcp://172.16.3.221:36025'. Reason: nanny-close-gracefully
2024-03-27 18:25:55,083 - distributed.dask_worker - INFO - End worker
