2024-04-05 22:34:39,312 - distributed.nanny - INFO -         Start Nanny at: 'tcp://172.16.3.169:39771'
2024-04-05 22:34:43,299 - distributed.worker - INFO -       Start worker at:   tcp://172.16.3.169:45860
2024-04-05 22:34:43,300 - distributed.worker - INFO -          Listening to:   tcp://172.16.3.169:45860
2024-04-05 22:34:43,300 - distributed.worker - INFO -           Worker name:             SLURMCluster-4
2024-04-05 22:34:43,300 - distributed.worker - INFO -          dashboard at:         172.16.3.169:37148
2024-04-05 22:34:43,300 - distributed.worker - INFO - Waiting to connect to:    tcp://172.16.3.67:45546
2024-04-05 22:34:43,300 - distributed.worker - INFO - -------------------------------------------------
2024-04-05 22:34:43,300 - distributed.worker - INFO -               Threads:                         36
2024-04-05 22:34:43,300 - distributed.worker - INFO -                Memory:                  37.25 GiB
2024-04-05 22:34:43,300 - distributed.worker - INFO -       Local Directory: /tmp/dask-worker-space/worker-jeh52pzs
2024-04-05 22:34:43,301 - distributed.worker - INFO - -------------------------------------------------
2024-04-05 22:34:43,315 - distributed.worker - INFO -         Registered to:    tcp://172.16.3.67:45546
2024-04-05 22:34:43,315 - distributed.worker - INFO - -------------------------------------------------
2024-04-05 22:34:43,315 - distributed.core - INFO - Starting established connection to tcp://172.16.3.67:45546
2024-04-05 22:36:31,683 - distributed.core - INFO - Event loop was unresponsive in Worker for 50.69s.  This is often caused by long-running GIL-holding functions or moving large chunks of data. This can cause timeouts and instability.
2024-04-05 22:36:31,686 - distributed.core - INFO - Connection to tcp://172.16.3.67:45546 has been closed.
2024-04-05 22:36:31,688 - distributed.worker - INFO - Stopping worker at tcp://172.16.3.169:45860. Reason: worker-handle-scheduler-connection-broken
2024-04-05 22:36:31,689 - distributed.batched - INFO - Batched Comm Closed <TCP (closed) Worker->Scheduler local=tcp://172.16.3.169:38068 remote=tcp://172.16.3.67:45546>
Traceback (most recent call last):
  File "/vortexfs1/home/anthony.meza/mambaforge/envs/atm_rivers/lib/python3.10/site-packages/distributed/batched.py", line 115, in _background_send
    nbytes = yield coro
  File "/vortexfs1/home/anthony.meza/mambaforge/envs/atm_rivers/lib/python3.10/site-packages/tornado/gen.py", line 767, in run
    value = future.result()
  File "/vortexfs1/home/anthony.meza/mambaforge/envs/atm_rivers/lib/python3.10/site-packages/distributed/comm/tcp.py", line 269, in write
    raise CommClosedError()
distributed.comm.core.CommClosedError
2024-04-05 22:36:31,699 - distributed.nanny - INFO - Closing Nanny gracefully at 'tcp://172.16.3.169:39771'. Reason: worker-handle-scheduler-connection-broken
2024-04-05 22:36:31,733 - distributed.worker - ERROR - Failed to communicate with scheduler during heartbeat.
Traceback (most recent call last):
  File "/vortexfs1/home/anthony.meza/mambaforge/envs/atm_rivers/lib/python3.10/site-packages/distributed/core.py", line 1431, in _connect
    comm = await connect(
  File "/vortexfs1/home/anthony.meza/mambaforge/envs/atm_rivers/lib/python3.10/site-packages/distributed/comm/core.py", line 292, in connect
    comm = await wait_for(
  File "/vortexfs1/home/anthony.meza/mambaforge/envs/atm_rivers/lib/python3.10/site-packages/distributed/utils.py", line 1878, in wait_for
    return await asyncio.wait_for(fut, timeout)
  File "/vortexfs1/home/anthony.meza/mambaforge/envs/atm_rivers/lib/python3.10/asyncio/tasks.py", line 432, in wait_for
    await waiter
asyncio.exceptions.CancelledError

During handling of the above exception, another exception occurred:

Traceback (most recent call last):
  File "/vortexfs1/home/anthony.meza/mambaforge/envs/atm_rivers/lib/python3.10/site-packages/distributed/worker.py", line 1237, in heartbeat
    response = await retry_operation(
  File "/vortexfs1/home/anthony.meza/mambaforge/envs/atm_rivers/lib/python3.10/site-packages/distributed/utils_comm.py", line 434, in retry_operation
    return await retry(
  File "/vortexfs1/home/anthony.meza/mambaforge/envs/atm_rivers/lib/python3.10/site-packages/distributed/utils_comm.py", line 413, in retry
    return await coro()
  File "/vortexfs1/home/anthony.meza/mambaforge/envs/atm_rivers/lib/python3.10/site-packages/distributed/core.py", line 1266, in send_recv_from_rpc
    comm = await self.pool.connect(self.addr)
  File "/vortexfs1/home/anthony.meza/mambaforge/envs/atm_rivers/lib/python3.10/site-packages/distributed/core.py", line 1510, in connect
    return await connect_attempt
  File "/vortexfs1/home/anthony.meza/mambaforge/envs/atm_rivers/lib/python3.10/site-packages/distributed/core.py", line 1454, in _connect
    raise CommClosedError(reason)
distributed.comm.core.CommClosedError: ConnectionPool closing.
2024-04-05 22:36:31,741 - distributed.nanny - INFO - Worker closed
2024-04-05 22:36:33,743 - distributed.nanny - ERROR - Worker process died unexpectedly
2024-04-05 22:36:35,435 - distributed.nanny - INFO - Closing Nanny at 'tcp://172.16.3.169:39771'. Reason: nanny-close-gracefully
2024-04-05 22:36:35,436 - distributed.dask_worker - INFO - End worker
